Workbook

Sheet Madeira Tratada
A1: Código Montana | B1: Código UFV | C1: Situação | D1: CNPJ | E1: Localização | F1: Data de entrada | G1: Início da análise | H1: Fim da análise | I1: Nome do Cliente | J1: Cidade | K1: Estado | L1: Tipo de Amostra | M1: E-mail | N1: Produto utilizado | O1: Formato da amostra | P1: Madeira | Q1: Indentificação de Amostra do cliente | R1: Motivo do Cancelamento | S1: Contato MOQ | T1: E-mail MOQ | U1: Montana avisou cliente | V1: Verificação Biológica | W1: Resultado | X1: Aplicação | Y1: Retenção | Z1: Norma ABNT | AA1: Grau penetração | AB1: Descrição Grau | AC1: Descrição Penetração | AD1: pH da solução | AE1: Densidade solução (g/cm³) | AF1: Temperatura | AG1: Concentração pelo termo | AH1: Grau do aspecto | AI1: Aspecto | AJ1: Descrição do aspecto | AK1: Diâmetro 1 (mm) | AL1: Diâmetro 2 (mm) | AM1: Diâmetro 3 (mm) | AN1: Diâmetro 4 (mm) | AO1: Diâmetro 5 (mm) | AP1: Diâmetro médio (cm) | AQ1: Comprim. 1 (mm) | AR1: Comprim. 2 (mm) | AS1: Comprim. 3 (mm) | AT1: Comprim. 4 (mm) | AU1: Comprim. 5 (mm) | AV1: Comprim. Médio (cm) | AW1: Massa 1 (g) | AX1: Massa 2 (g) | AY1: Massa 3 (g) | AZ1: Massa 4 (g) | BA1: Massa 5 (g) | BB1: Massa média (g) | BC1: Volume (cm³) | BD1: Densidade (g/cm³) | BE1: Densidade (Kg/m³) | BF1: Cromo (%) | BG1: Cobre (%) | BH1: Arsênio (%) | BI1: Balanço Total | BJ1: Balanço Cromo % | BK1: Balanço Cobre % | BL1: Balanço Arsênio % | BM1: Balanço Total % | BN1: Retenção Cromo (Kg/m³) | BO1: Retenção Cobre (Kg/m³) | BP1: Retenção Arsênio (Kg/m³) | BQ1: Retenção/concentração | BR1: Observação
B2: UFV-M-01 | C2: Finalizada | F2: 45328 | G2: 45329 | H2: 45329 | I2: Lua Madeira Imunizada | J2: Nova União | K2: MG | L2: Madeira | N2: CCA - C | O2: Torete | P2: Eucalyptus | Q2: - | X2: Mourões | Y2: =IF(X2='Listas suspensas'!$A$21,'Listas suspensas'!$B$23,IF(X2='Listas suspensas'!$A$22,'Listas suspensas'!$B$23,IF(X2='Listas suspensas'!$A$23,'Listas suspensas'!$B$22,IF(X2='Listas suspensas'!$A$26,'Listas suspensas'!$B$22,IF(X2='Listas suspensas'!$A$32,'Listas suspensas'!$B$22,IF(X2='Listas suspensas'!$A$33,'Listas suspensas'!$B$21,IF(X2='Listas suspensas'!$A$24,'Listas suspensas'!$B$22,IF(X2='Listas suspensas'!$A$30,'Listas suspensas'!$B$21,"")))))))) -> 6.5 | Z2: NBR 16143 | AA2: 3 | AB2: =IF(AA2='Listas suspensas'!$A$2,'Listas suspensas'!$B$2,IF(AA2='Listas suspensas'!$A$3,'Listas suspensas'!$B$3,IF(AA2='Listas suspensas'!$A$4,'Listas suspensas'!$B$4,IF(AA2='Listas suspensas'!$A$5,'Listas suspensas'!$B$5,IF(AA2='Listas suspensas'!$A$6,'Listas suspensas'!$B$6,""))))) -> Parcial e regular | AC2: =IF(AA2='Listas suspensas'!$A$2,'Listas suspensas'!$C$2,IF(AA2='Listas suspensas'!$A$3,'Listas suspensas'!$C$3,IF(AA2='Listas suspensas'!$A$4,'Listas suspensas'!$C$4,IF(AA2='Listas suspensas'!$A$5,'Listas suspensas'!$C$5,IF(AA2='Listas suspensas'!$A$6,'Listas suspensas'!$C$6,""))))) -> Indica a penetração uniforme, mas não total pela extensão do alburno. | AK2: 11.12 | AL2: 11.37 | AM2: 11.12 | AN2: 11.3 | AO2: 10.77 | AP2: =AVERAGE(AK2:AO2)/10 -> 1.1136 | AQ2: 17.5 | AR2: 17.56 | AS2: 20.17 | AT2: 14.34 | AU2: 16.97 | AV2: =AVERAGE(AQ2:AU2)/10 -> 1.7308 | AW2: 1.3948 | AX2: 1.5416 | AY2: 1.7109 | AZ2: 1.2993 | BA2: 1.3403 | BB2: =AVERAGE(AW2:BA2) -> 1.45738 | BC2: =PI()*(AP2/2)^2*AV2 -> 1.6857579 | BE2: =(BB2/BC2)*1000 -> 864.52507 | BF2: 0.333 | BG2: 0.171 | BH2: 0.291 | BI2: =SUM(BF2:BH2) -> 0.795 | BJ2: 41.8 | BK2: 21.6 | BL2: 36.6 | BM2: =ROUND(SUM(BJ2:BL2),2) -> 100 | BN2: =ROUND((BF2/100)*BE2,2) -> 2.88 | BO2: =ROUND((BG2/100)*BE2,2) -> 1.48 | BP2: =ROUND((BH2/100)*BE2,2) -> 2.52 | BQ2: =ROUND(SUM(BN2:BP2),2) -> 6.88 | BR2: =IF(OR(AND(X2="Mourões", BQ2>=6.5),AND(X2="Postes", BQ2>=9.6),AND(X2="Dormentes", BQ2>=9.6),AND(X2="Estacas", BQ2>=6.5),AND(X2="Cruzetas", BQ2>=6.5),AND(X2="Outros - Solo", BQ2>=6.5),AND(X2="Outros - Suspenso",BQ2>=4),AND(X2="Deck",BQ2>=4)),'Listas suspensas'!$C$21,'Listas suspensas'!$C$22) -> Os resultados da análise química apresentaram uma retenção do produto de acordo com o padrão mínimo exigido pela norma ABNT NBR 16143
B3: UFV-M-02 | C3: Finalizada | F3: 45328 | G3: 45329 | H3: 45330 | I3: Nova União | J3: Turmalina | K3: MG | L3: Madeira | N3: CCA - C | O3: Torete | P3: Eucalyptus | Q3: Amostra 1 | X3: Mourões | Y3: =IF(X3='Listas suspensas'!$A$21,'Listas suspensas'!$B$23,IF(X3='Listas suspensas'!$A$22,'Listas suspensas'!$B$23,IF(X3='Listas suspensas'!$A$23,'Listas suspensas'!$B$22,IF(X3='Listas suspensas'!$A$26,'Listas suspensas'!$B$22,IF(X3='Listas suspensas'!$A$32,'Listas suspensas'!$B$22,IF(X3='Listas suspensas'!$A$33,'Listas suspensas'!$B$21,IF(X3='Listas suspensas'!$A$24,'Listas suspensas'!$B$22,IF(X3='Listas suspensas'!$A$30,'Listas suspensas'!$B$21,"")))))))) -> 6.5 | Z3: NBR 16143 | AA3: 3 | AB3: =IF(AA3='Listas suspensas'!$A$2,'Listas suspensas'!$B$2,IF(AA3='Listas suspensas'!$A$3,'Listas suspensas'!$B$3,IF(AA3='Listas suspensas'!$A$4,'Listas suspensas'!$B$4,IF(AA3='Listas suspensas'!$A$5,'Listas suspensas'!$B$5,IF(AA3='Listas suspensas'!$A$6,'Listas suspensas'!$B$6,""))))) -> Parcial e regular | AC3: =IF(AA3='Listas suspensas'!$A$2,'Listas suspensas'!$C$2,IF(AA3='Listas suspensas'!$A$3,'Listas suspensas'!$C$3,IF(AA3='Listas suspensas'!$A$4,'Listas suspensas'!$C$4,IF(AA3='Listas suspensas'!$A$5,'Listas suspensas'!$C$5,IF(AA3='Listas suspensas'!$A$6,'Listas suspensas'!$C$6,""))))) -> Indica a penetração uniforme, mas não total pela extensão do alburno. | AK3: 12 | AL3: 11.59 | AM3: 12.05 | AN3: 12.05 | AO3: 11.93 | AP3: =AVERAGE(AK3:AO3)/10 -> 1.1924 | AQ3: 15.69 | AR3: 20.67 | AS3: 12.59 | AT3: 11.19 | AU3: 16.42 | AV3: =AVERAGE(AQ3:AU3)/10 -> 1.5312 | AW3: 1.3574 | AX3: 1.9383 | AY3: 1.081 | AZ3: 1.0586 | BA3: 1.5283 | BB3: =AVERAGE(AW3:BA3) -> 1.39272 | BC3: =PI()*(AP3/2)^2*AV3 -> 1.7098804 | BE3: =(BB3/BC3)*1000 -> 814.5131 | BF3: 0.253 | BG3: 0.146 | BH3: 0.249 | BI3: =SUM(BF3:BH3) -> 0.648 | BJ3: 39.1 | BK3: 22.5 | BL3: 38.4 | BM3: =ROUND(SUM(BJ3:BL3),2) -> 100 | BN3: =ROUND((BF3/100)*BE3,2) -> 2.06 | BO3: =ROUND((BG3/100)*BE3,2) -> 1.19 | BP3: =ROUND((BH3/100)*BE3,2) -> 2.03 | BQ3: =ROUND(SUM(BN3:BP3),2) -> 5.28 | BR3: =IF(OR(AND(X3="Mourões", BQ3>=6.5),AND(X3="Postes", BQ3>=9.6),AND(X3="Dormentes", BQ3>=9.6),AND(X3="Estacas", BQ3>=6.5),AND(X3="Cruzetas", BQ3>=6.5),AND(X3="Outros - Solo", BQ3>=6.5),AND(X3="Outros - Suspenso",BQ3>=4),AND(X3="Deck",BQ3>=4)),'Listas suspensas'!$C$21,'Listas suspensas'!$C$22) -> Os resultados da análise química apresentaram uma retenção do produto inferior ao padrão mínimo exigido pela norma ABNT NBR 16143
B4: UFV-M-03 | C4: Finalizada | F4: 45328 | G4: 45329 | H4: 45330 | I4: Nova União | J4: Turmalina | K4: MG | L4: Madeira | N4: CCA - C | O4: Torete | P4: Eucalyptus | Q4: Amostra 2 | X4: Mourões | Y4: =IF(X4='Listas suspensas'!$A$21,'Listas suspensas'!$B$23,IF(X4='Listas suspensas'!$A$22,'Listas suspensas'!$B$23,IF(X4='Listas suspensas'!$A$23,'Listas suspensas'!$B$22,IF(X4='Listas suspensas'!$A$26,'Listas suspensas'!$B$22,IF(X4='Listas suspensas'!$A$32,'Listas suspensas'!$B$22,IF(X4='Listas suspensas'!$A$33,'Listas suspensas'!$B$21,IF(X4='Listas suspensas'!$A$24,'Listas suspensas'!$B$22,IF(X4='Listas suspensas'!$A$30,'Listas suspensas'!$B$21,"")))))))) -> 6.5 | Z4: NBR 16143 | AA4: 2 | AB4: =IF(AA4='Listas suspensas'!$A$2,'Listas suspensas'!$B$2,IF(AA4='Listas suspensas'!$A$3,'Listas suspensas'!$B$3,IF(AA4='Listas suspensas'!$A$4,'Listas suspensas'!$B$4,IF(AA4='Listas suspensas'!$A$5,'Listas suspensas'!$B$5,IF(AA4='Listas suspensas'!$A$6,'Listas suspensas'!$B$6,""))))) -> Profunda e irregular | AC4: =IF(AA4='Listas suspensas'!$A$2,'Listas suspensas'!$C$2,IF(AA4='Listas suspensas'!$A$3,'Listas suspensas'!$C$3,IF(AA4='Listas suspensas'!$A$4,'Listas suspensas'!$C$4,IF(AA4='Listas suspensas'!$A$5,'Listas suspensas'!$C$5,IF(AA4='Listas suspensas'!$A$6,'Listas suspensas'!$C$6,""))))) -> Indica a penetração profunda, mas desuniforme em toda a extensão do alburno. | AK4: 11.49 | AL4: 11.58 | AM4: 12.01 | AN4: 11.95 | AO4: 11.96 | AP4: =AVERAGE(AK4:AO4)/10 -> 1.1798 | AQ4: 13.77 | AR4: 14.03 | AS4: 12.4 | AT4: 12.99 | AU4: 15.1 | AV4: =AVERAGE(AQ4:AU4)/10 -> 1.3658 | AW4: 1.2413 | AX4: 1.0814 | AY4: 1.2024 | AZ4: 1.2591 | BA4: 1.3569 | BB4: =AVERAGE(AW4:BA4) -> 1.22822 | BC4: =PI()*(AP4/2)^2*AV4 -> 1.4931168 | BE4: =(BB4/BC4)*1000 -> 822.58804 | BF4: 0.215 | BG4: 0.103 | BH4: 0.169 | BI4: =SUM(BF4:BH4) -> 0.487 | BJ4: 44.2 | BK4: 21.1 | BL4: 34.7 | BM4: =ROUND(SUM(BJ4:BL4),2) -> 100 | BN4: =ROUND((BF4/100)*BE4,2) -> 1.77 | BO4: =ROUND((BG4/100)*BE4,2) -> 0.85 | BP4: =ROUND((BH4/100)*BE4,2) -> 1.39 | BQ4: =ROUND(SUM(BN4:BP4),2) -> 4.01 | BR4: =IF(OR(AND(X4="Mourões", BQ4>=6.5),AND(X4="Postes", BQ4>=9.6),AND(X4="Dormentes", BQ4>=9.6),AND(X4="Estacas", BQ4>=6.5),AND(X4="Cruzetas", BQ4>=6.5),AND(X4="Outros - Solo", BQ4>=6.5),AND(X4="Outros - Suspenso",BQ4>=4),AND(X4="Deck",BQ4>=4)),'Listas suspensas'!$C$21,'Listas suspensas'!$C$22) -> Os resultados da análise química apresentaram uma retenção do produto inferior ao padrão mínimo exigido pela norma ABNT NBR 16143
B5: UFV-M-04 | C5: Finalizada | F5: 45328 | G5: 45329 | H5: 45330 | I5: Nova União | J5: Turmalina | K5: MG | L5: Madeira | N5: CCA - C | O5: Torete | P5: Eucalyptus | Q5: Amostra 3 | X5: Mourões | Y5: =IF(X5='Listas suspensas'!$A$21,'Listas suspensas'!$B$23,IF(X5='Listas suspensas'!$A$22,'Listas suspensas'!$B$23,IF(X5='Listas suspensas'!$A$23,'Listas suspensas'!$B$22,IF(X5='Listas suspensas'!$A$26,'Listas suspensas'!$B$22,IF(X5='Listas suspensas'!$A$32,'Listas suspensas'!$B$22,IF(X5='Listas suspensas'!$A$33,'Listas suspensas'!$B$21,IF(X5='Listas suspensas'!$A$24,'Listas suspensas'!$B$22,IF(X5='Listas suspensas'!$A$30,'Listas suspensas'!$B$21,"")))))))) -> 6.5 | Z5: NBR 16143 | AA5: 3 | AB5: =IF(AA5='Listas suspensas'!$A$2,'Listas suspensas'!$B$2,IF(AA5='Listas suspensas'!$A$3,'Listas suspensas'!$B$3,IF(AA5='Listas suspensas'!$A$4,'Listas suspensas'!$B$4,IF(AA5='Listas suspensas'!$A$5,'Listas suspensas'!$B$5,IF(AA5='Listas suspensas'!$A$6,'Listas suspensas'!$B$6,""))))) -> Parcial e regular | AC5: =IF(AA5='Listas suspensas'!$A$2,'Listas suspensas'!$C$2,IF(AA5='Listas suspensas'!$A$3,'Listas suspensas'!$C$3,IF(AA5='Listas suspensas'!$A$4,'Listas suspensas'!$C$4,IF(AA5='Listas suspensas'!$A$5,'Listas suspensas'!$C$5,IF(AA5='Listas suspensas'!$A$6,'Listas suspensas'!$C$6,""))))) -> Indica a penetração uniforme, mas não total pela extensão do alburno. | AK5: 11.94 | AL5: 12.02 | AM5: 11.93 | AN5: 11.94 | AO5: 11.96 | AP5: =AVERAGE(AK5:AO5)/10 -> 1.1958 | AQ5: 11.79 | AR5: 10.53 | AS5: 15.61 | AT5: 14.8 | AU5: 13.05 | AV5: =AVERAGE(AQ5:AU5)/10 -> 1.3156 | AW5: 1.0178 | AX5: 0.9848 | AY5: 1.496 | AZ5: 1.4151 | BA5: 1.1901 | BB5: =AVERAGE(AW5:BA5) -> 1.22076 | BC5: =PI()*(AP5/2)^2*AV5 -> 1.4775114 | BE5: =(BB5/BC5)*1000 -> 826.22712 | BF5: 0.178 | BG5: 0.095 | BH5: 0.162 | BI5: =SUM(BF5:BH5) -> 0.435 | BJ5: 40.9 | BK5: 21.8 | BL5: 37.3 | BM5: =ROUND(SUM(BJ5:BL5),2) -> 100 | BN5: =ROUND((BF5/100)*BE5,2) -> 1.47 | BO5: =ROUND((BG5/100)*BE5,2) -> 0.78 | BP5: =ROUND((BH5/100)*BE5,2) -> 1.34 | BQ5: =ROUND(SUM(BN5:BP5),2) -> 3.59 | BR5: =IF(OR(AND(X5="Mourões", BQ5>=6.5),AND(X5="Postes", BQ5>=9.6),AND(X5="Dormentes", BQ5>=9.6),AND(X5="Estacas", BQ5>=6.5),AND(X5="Cruzetas", BQ5>=6.5),AND(X5="Outros - Solo", BQ5>=6.5),AND(X5="Outros - Suspenso",BQ5>=4),AND(X5="Deck",BQ5>=4)),'Listas suspensas'!$C$21,'Listas suspensas'!$C$22) -> Os resultados da análise química apresentaram uma retenção do produto inferior ao padrão mínimo exigido pela norma ABNT NBR 16143
B6: UFV-M-05 | C6: Finalizada | D6: 03.676.002/0001-93 | F6: 45328 | G6: 45329 | H6: 45330 | I6: Madtrat | J6: Santa Cruz do Rio Pardo | K6: SP | L6: Madeira | M6: qualidade@madtrat.com.br | N6: CCA - C | O6: Bagueta | P6: Eucalyptus | Q6: Mourão | X6: Mourões | Y6: =IF(X6='Listas suspensas'!$A$21,'Listas suspensas'!$B$23,IF(X6='Listas suspensas'!$A$22,'Listas suspensas'!$B$23,IF(X6='Listas suspensas'!$A$23,'Listas suspensas'!$B$22,IF(X6='Listas suspensas'!$A$26,'Listas suspensas'!$B$22,IF(X6='Listas suspensas'!$A$32,'Listas suspensas'!$B$22,IF(X6='Listas suspensas'!$A$33,'Listas suspensas'!$B$21,IF(X6='Listas suspensas'!$A$24,'Listas suspensas'!$B$22,IF(X6='Listas suspensas'!$A$30,'Listas suspensas'!$B$21,"")))))))) -> 6.5 | Z6: NBR 16143 | AA6: 1 | AB6: =IF(AA6='Listas suspensas'!$A$2,'Listas suspensas'!$B$2,IF(AA6='Listas suspensas'!$A$3,'Listas suspensas'!$B$3,IF(AA6='Listas suspensas'!$A$4,'Listas suspensas'!$B$4,IF(AA6='Listas suspensas'!$A$5,'Listas suspensas'!$B$5,IF(AA6='Listas suspensas'!$A$6,'Listas suspensas'!$B$6,""))))) -> Profunda e regular | AC6: =IF(AA6='Listas suspensas'!$A$2,'Listas suspensas'!$C$2,IF(AA6='Listas suspensas'!$A$3,'Listas suspensas'!$C$3,IF(AA6='Listas suspensas'!$A$4,'Listas suspensas'!$C$4,IF(AA6='Listas suspensas'!$A$5,'Listas suspensas'!$C$5,IF(AA6='Listas suspensas'!$A$6,'Listas suspensas'!$C$6,""))))) -> Indica a penetração profunda e uniforme em toda a extensão do alburno. | AK6: 12.07 | AL6: 11.87 | AM6: 10.87 | AN6: 11.34 | AO6: 11.2 | AP6: =AVERAGE(AK6:AO6)/10 -> 1.147 | AQ6: 19.78 | AR6: 16.6 | AS6: 17.56 | AT6: 16.21 | AU6: 15.87 | AV6: =AVERAGE(AQ6:AU6)/10 -> 1.7204 | AW6: 1.7981 | AX6: 1.5502 | AY6: 1.7351 | AZ6: 1.5215 | BA6: 1.4194 | BB6: =AVERAGE(AW6:BA6) -> 1.60486 | BC6: =PI()*(AP6/2)^2*AV6 -> 1.7776496 | BE6: =(BB6/BC6)*1000 -> 902.79886 | BF6: 0.364 | BG6: 0.16 | BH6: 0.263 | BI6: =SUM(BF6:BH6) -> 0.787 | BJ6: 46.2 | BK6: 20.3 | BL6: 33.5 | BM6: =ROUND(SUM(BJ6:BL6),2) -> 100 | BN6: =ROUND((BF6/100)*BE6,2) -> 3.29 | BO6: =ROUND((BG6/100)*BE6,2) -> 1.44 | BP6: =ROUND((BH6/100)*BE6,2) -> 2.37 | BQ6: =ROUND(SUM(BN6:BP6),2) -> 7.1 | BR6: =IF(OR(AND(X6="Mourões", BQ6>=6.5),AND(X6="Postes", BQ6>=9.6),AND(X6="Dormentes", BQ6>=9.6),AND(X6="Estacas", BQ6>=6.5),AND(X6="Cruzetas", BQ6>=6.5),AND(X6="Outros - Solo", BQ6>=6.5),AND(X6="Outros - Suspenso",BQ6>=4),AND(X6="Deck",BQ6>=4)),'Listas suspensas'!$C$21,'Listas suspensas'!$C$22) -> Os resultados da análise química apresentaram uma retenção do produto de acordo com o padrão mínimo exigido pela norma ABNT NBR 16143
B7: UFV-M-06 | C7: Finalizada | D7: 03.676.002/0001-93 | F7: 45328 | G7: 45329 | H7: 45330 | I7: Madtrat | J7: Santa Cruz do Rio Pardo | K7: SP | L7: Madeira | M7: qualidade@madtrat.com.br | N7: CCA - C | O7: Bagueta | P7: Eucalyptus | Q7: Poste Lote 16 | X7: Postes | Y7: =IF(X7='Listas suspensas'!$A$21,'Listas suspensas'!$B$23,IF(X7='Listas suspensas'!$A$22,'Listas suspensas'!$B$23,IF(X7='Listas suspensas'!$A$23,'Listas suspensas'!$B$22,IF(X7='Listas suspensas'!$A$26,'Listas suspensas'!$B$22,IF(X7='Listas suspensas'!$A$32,'Listas suspensas'!$B$22,IF(X7='Listas suspensas'!$A$33,'Listas suspensas'!$B$21,IF(X7='Listas suspensas'!$A$24,'Listas suspensas'!$B$22,IF(X7='Listas suspensas'!$A$30,'Listas suspensas'!$B$21,"")))))))) -> 9.6 | Z7: NBR 16143 | AA7: 1 | AB7: =IF(AA7='Listas suspensas'!$A$2,'Listas suspensas'!$B$2,IF(AA7='Listas suspensas'!$A$3,'Listas suspensas'!$B$3,IF(AA7='Listas suspensas'!$A$4,'Listas suspensas'!$B$4,IF(AA7='Listas suspensas'!$A$5,'Listas suspensas'!$B$5,IF(AA7='Listas suspensas'!$A$6,'Listas suspensas'!$B$6,""))))) -> Profunda e regular | AC7: =IF(AA7='Listas suspensas'!$A$2,'Listas suspensas'!$C$2,IF(AA7='Listas suspensas'!$A$3,'Listas suspensas'!$C$3,IF(AA7='Listas suspensas'!$A$4,'Listas suspensas'!$C$4,IF(AA7='Listas suspensas'!$A$5,'Listas suspensas'!$C$5,IF(AA7='Listas suspensas'!$A$6,'Listas suspensas'!$C$6,""))))) -> Indica a penetração profunda e uniforme em toda a extensão do alburno. | AK7: 11.17 | AL7: 11.92 | AM7: 11.99 | AN7: 10.68 | AO7: 11.11 | AP7: =AVERAGE(AK7:AO7)/10 -> 1.1374 | AQ7: 13.15 | AR7: 20.61 | AS7: 20.54 | AT7: 14.61 | AU7: 18.76 | AV7: =AVERAGE(AQ7:AU7)/10 -> 1.7534 | AW7: 1.3202 | AX7: 1.8622 | AY7: 1.9167 | AZ7: 1.4303 | BA7: 1.6906 | BB7: =AVERAGE(AW7:BA7) -> 1.644 | BC7: =PI()*(AP7/2)^2*AV7 -> 1.7815472 | BE7: =(BB7/BC7)*1000 -> 922.7934 | BF7: 0.424 | BG7: 0.202 | BH7: 0.36 | BI7: =SUM(BF7:BH7) -> 0.986 | BJ7: 43 | BK7: 20.5 | BL7: 36.5 | BM7: =ROUND(SUM(BJ7:BL7),2) -> 100 | BN7: =ROUND((BF7/100)*BE7,2) -> 3.91 | BO7: =ROUND((BG7/100)*BE7,2) -> 1.86 | BP7: =ROUND((BH7/100)*BE7,2) -> 3.32 | BQ7: =ROUND(SUM(BN7:BP7),2) -> 9.09 | BR7: =IF(OR(AND(X7="Mourões", BQ7>=6.5),AND(X7="Postes", BQ7>=9.6),AND(X7="Dormentes", BQ7>=9.6),AND(X7="Estacas", BQ7>=6.5),AND(X7="Cruzetas", BQ7>=6.5),AND(X7="Outros - Solo", BQ7>=6.5),AND(X7="Outros - Suspenso",BQ7>=4),AND(X7="Deck",BQ7>=4)),'Listas suspensas'!$C$21,'Listas suspensas'!$C$22) -> Os resultados da análise química apresentaram uma retenção do produto inferior ao padrão mínimo exigido pela norma ABNT NBR 16143
B8: UFV-M-07 | C8: Finalizada | D8: 03.676.002/0001-93 | F8: 45329 | G8: 45329 | H8: 45330 | I8: Madtrat | J8: Santa Cruz do Rio Pardo | K8: SP | L8: Madeira | M8: qualidade@madtrat.com.br | N8: CCA - C | O8: Bagueta | P8: Eucalyptus | Q8: VCS0001 | X8: Outros - Solo | Y8: =IF(X8='Listas suspensas'!$A$21,'Listas suspensas'!$B$23,IF(X8='Listas suspensas'!$A$22,'Listas suspensas'!$B$23,IF(X8='Listas suspensas'!$A$23,'Listas suspensas'!$B$22,IF(X8='Listas suspensas'!$A$26,'Listas suspensas'!$B$22,IF(X8='Listas suspensas'!$A$32,'Listas suspensas'!$B$22,IF(X8='Listas suspensas'!$A$33,'Listas suspensas'!$B$21,IF(X8='Listas suspensas'!$A$24,'Listas suspensas'!$B$22,IF(X8='Listas suspensas'!$A$30,'Listas suspensas'!$B$21,"")))))))) -> 6.5 | Z8: NBR 16143 | AA8: 2 | AB8: =IF(AA8='Listas suspensas'!$A$2,'Listas suspensas'!$B$2,IF(AA8='Listas suspensas'!$A$3,'Listas suspensas'!$B$3,IF(AA8='Listas suspensas'!$A$4,'Listas suspensas'!$B$4,IF(AA8='Listas suspensas'!$A$5,'Listas suspensas'!$B$5,IF(AA8='Listas suspensas'!$A$6,'Listas suspensas'!$B$6,""))))) -> Profunda e irregular | AC8: =IF(AA8='Listas suspensas'!$A$2,'Listas suspensas'!$C$2,IF(AA8='Listas suspensas'!$A$3,'Listas suspensas'!$C$3,IF(AA8='Listas suspensas'!$A$4,'Listas suspensas'!$C$4,IF(AA8='Listas suspensas'!$A$5,'Listas suspensas'!$C$5,IF(AA8='Listas suspensas'!$A$6,'Listas suspensas'!$C$6,""))))) -> Indica a penetração profunda, mas desuniforme em toda a extensão do alburno. | AK8: 12.05 | AL8: 11.93 | AM8: 11.93 | AP8: =AVERAGE(AK8:AO8)/10 -> 1.197 | AQ8: 19.17 | AR8: 18.25 | AS8: 18.08 | AV8: =AVERAGE(AQ8:AU8)/10 -> 1.85 | AW8: 1.7944 | AX8: 1.6945 | AY8: 1.6107 | BB8: =AVERAGE(AW8:BA8) -> 1.6998667 | BC8: =PI()*(AP8/2)^2*AV8 -> 2.0818523 | BE8: =(BB8/BC8)*1000 -> 816.51647 | BF8: 0.546 | BG8: 0.252 | BH8: 0.45 | BI8: =SUM(BF8:BH8) -> 1.248 | BJ8: 43.7 | BK8: 20.2 | BL8: 36.1 | BM8: =ROUND(SUM(BJ8:BL8),2) -> 100 | BN8: =ROUND((BF8/100)*BE8,2) -> 4.46 | BO8: =ROUND((BG8/100)*BE8,2) -> 2.06 | BP8: =ROUND((BH8/100)*BE8,2) -> 3.67 | BQ8: =ROUND(SUM(BN8:BP8),2) -> 10.19 | BR8: =IF(OR(AND(X8="Mourões", BQ8>=6.5),AND(X8="Postes", BQ8>=9.6),AND(X8="Dormentes", BQ8>=9.6),AND(X8="Estacas", BQ8>=6.5),AND(X8="Cruzetas", BQ8>=6.5),AND(X8="Outros - Solo", BQ8>=6.5),AND(X8="Outros - Suspenso",BQ8>=4),AND(X8="Deck",BQ8>=4)),'Listas suspensas'!$C$21,'Listas suspensas'!$C$22) -> Os resultados da análise química apresentaram uma retenção do produto de acordo com o padrão mínimo exigido pela norma ABNT NBR 16143
B9: UFV-M-08 | C9: Finalizada | F9: 45350 | G9: 45350 | H9: 45351 | I9: Lua Madeira Imunizada | J9: Nova União | K9: MG | L9: Madeira | M9: producao@luamadeira.com.br | N9: CCA - C | O9: Serrado 15 cm | P9: Eucalyptus | Q9: I1 | X9: Mourões | Y9: =IF(X9='Listas suspensas'!$A$21,'Listas suspensas'!$B$23,IF(X9='Listas suspensas'!$A$22,'Listas suspensas'!$B$23,IF(X9='Listas suspensas'!$A$23,'Listas suspensas'!$B$22,IF(X9='Listas suspensas'!$A$26,'Listas suspensas'!$B$22,IF(X9='Listas suspensas'!$A$32,'Listas suspensas'!$B$22,IF(X9='Listas suspensas'!$A$33,'Listas suspensas'!$B$21,IF(X9='Listas suspensas'!$A$24,'Listas suspensas'!$B$22,IF(X9='Listas suspensas'!$A$30,'Listas suspensas'!$B$21,"")))))))) -> 6.5 | Z9: NBR 16143 | AA9: 3 | AB9: =IF(AA9='Listas suspensas'!$A$2,'Listas suspensas'!$B$2,IF(AA9='Listas suspensas'!$A$3,'Listas suspensas'!$B$3,IF(AA9='Listas suspensas'!$A$4,'Listas suspensas'!$B$4,IF(AA9='Listas suspensas'!$A$5,'Listas suspensas'!$B$5,IF(AA9='Listas suspensas'!$A$6,'Listas suspensas'!$B$6,""))))) -> Parcial e regular | AC9: =IF(AA9='Listas suspensas'!$A$2,'Listas suspensas'!$C$2,IF(AA9='Listas suspensas'!$A$3,'Listas suspensas'!$C$3,IF(AA9='Listas suspensas'!$A$4,'Listas suspensas'!$C$4,IF(AA9='Listas suspensas'!$A$5,'Listas suspensas'!$C$5,IF(AA9='Listas suspensas'!$A$6,'Listas suspensas'!$C$6,""))))) -> Indica a penetração uniforme, mas não total pela extensão do alburno. | AK9: 11.02 | AL9: 10.94 | AM9: 11.25 | AN9: 11.2 | AO9: 11.25 | AP9: =AVERAGE(AK9:AO9)/10 -> 1.1132 | AQ9: 15.29 | AR9: 15.56 | AS9: 14.77 | AT9: 12.56 | AU9: 15.57 | AV9: =AVERAGE(AQ9:AU9)/10 -> 1.475 | AW9: 1.3813 | AX9: 1.2688 | AY9: 1.3427 | AZ9: 1.0205 | BA9: 1.2435 | BB9: =AVERAGE(AW9:BA9) -> 1.25136 | BC9: =PI()*(AP9/2)^2*AV9 -> 1.435583 | BE9: =(BB9/BC9)*1000 -> 871.67376 | BF9: 0.383 | BG9: 0.206 | BH9: 0.408 | BI9: =SUM(BF9:BH9) -> 0.997 | BJ9: 38.4 | BK9: 20.6 | BL9: 41 | BM9: =ROUND(SUM(BJ9:BL9),2) -> 100 | BN9: =ROUND((BF9/100)*BE9,2) -> 3.34 | BO9: =ROUND((BG9/100)*BE9,2) -> 1.8 | BP9: =ROUND((BH9/100)*BE9,2) -> 3.56 | BQ9: =ROUND(SUM(BN9:BP9),2) -> 8.7 | BR9: =IF(OR(AND(X9="Mourões", BQ9>=6.5),AND(X9="Postes", BQ9>=9.6),AND(X9="Dormentes", BQ9>=9.6),AND(X9="Estacas", BQ9>=6.5),AND(X9="Cruzetas", BQ9>=6.5),AND(X9="Outros - Solo", BQ9>=6.5),AND(X9="Outros - Suspenso",BQ9>=4),AND(X9="Deck",BQ9>=4)),'Listas suspensas'!$C$21,'Listas suspensas'!$C$22) -> Os resultados da análise química apresentaram uma retenção do produto de acordo com o padrão mínimo exigido pela norma ABNT NBR 16143
B10: UFV-M-09 | C10: Finalizada | F10: 45358 | G10: 45358 | H10: 45364 | I10: LiptosFlora | J10: Tangará da Serra | K10: MT | L10: Madeira | N10: CCA - C | O10: Bagueta | P10: Eucalyptus | Q10: Amostra 01 (8x10) | X10: Mourões | Y10: =IF(X10='Listas suspensas'!$A$21,'Listas suspensas'!$B$23,IF(X10='Listas suspensas'!$A$22,'Listas suspensas'!$B$23,IF(X10='Listas suspensas'!$A$23,'Listas suspensas'!$B$22,IF(X10='Listas suspensas'!$A$26,'Listas suspensas'!$B$22,IF(X10='Listas suspensas'!$A$32,'Listas suspensas'!$B$22,IF(X10='Listas suspensas'!$A$33,'Listas suspensas'!$B$21,IF(X10='Listas suspensas'!$A$24,'Listas suspensas'!$B$22,IF(X10='Listas suspensas'!$A$30,'Listas suspensas'!$B$21,"")))))))) -> 6.5 | Z10: NBR 16143 | AA10: 2 | AB10: =IF(AA10='Listas suspensas'!$A$2,'Listas suspensas'!$B$2,IF(AA10='Listas suspensas'!$A$3,'Listas suspensas'!$B$3,IF(AA10='Listas suspensas'!$A$4,'Listas suspensas'!$B$4,IF(AA10='Listas suspensas'!$A$5,'Listas suspensas'!$B$5,IF(AA10='Listas suspensas'!$A$6,'Listas suspensas'!$B$6,""))))) -> Profunda e irregular | AC10: =IF(AA10='Listas suspensas'!$A$2,'Listas suspensas'!$C$2,IF(AA10='Listas suspensas'!$A$3,'Listas suspensas'!$C$3,IF(AA10='Listas suspensas'!$A$4,'Listas suspensas'!$C$4,IF(AA10='Listas suspensas'!$A$5,'Listas suspensas'!$C$5,IF(AA10='Listas suspensas'!$A$6,'Listas suspensas'!$C$6,""))))) -> Indica a penetração profunda, mas desuniforme em toda a extensão do alburno. | AK10: 11.72 | AL10: 11.9 | AM10: 10.87 | AN10: 11.75 | AO10: 11.47 | AP10: =AVERAGE(AK10:AO10)/10 -> 1.1542 | AQ10: 15.21 | AR10: 14.2 | AS10: 13.52 | AT10: 12.66 | AU10: 15.09 | AV10: =AVERAGE(AQ10:AU10)/10 -> 1.4136 | AW10: 1.1437 | AX10: 1.1109 | AY10: 1.0095 | AZ10: 1.0319 | BA10: 1.1565 | BB10: =AVERAGE(AW10:BA10) -> 1.0905 | BC10: =PI()*(AP10/2)^2*AV10 -> 1.4790354 | BE10: =(BB10/BC10)*1000 -> 737.30489 | BF10: 0.368 | BG10: 0.184 | BH10: 0.327 | BI10: =SUM(BF10:BH10) -> 0.879 | BJ10: 41.9 | BK10: 20.9 | BL10: 37.2 | BM10: =ROUND(SUM(BJ10:BL10),2) -> 100 | BN10: =ROUND((BF10/100)*BE10,2) -> 2.71 | BO10: =ROUND((BG10/100)*BE10,2) -> 1.36 | BP10: =ROUND((BH10/100)*BE10,2) -> 2.41 | BQ10: =ROUND(SUM(BN10:BP10),2) -> 6.48 | BR10: =IF(OR(AND(X10="Mourões", BQ10>=6.5),AND(X10="Postes", BQ10>=9.6),AND(X10="Dormentes", BQ10>=9.6),AND(X10="Estacas", BQ10>=6.5),AND(X10="Cruzetas", BQ10>=6.5),AND(X10="Outros - Solo", BQ10>=6.5),AND(X10="Outros - Suspenso",BQ10>=4),AND(X10="Deck",BQ10>=4)),'Listas suspensas'!$C$21,'Listas suspensas'!$C$22) -> Os resultados da análise química apresentaram uma retenção do produto inferior ao padrão mínimo exigido pela norma ABNT NBR 16143
B11: UFV-M-10 | C11: Finalizada | F11: 45358 | G11: 45358 | H11: 45364 | I11: LiptosFlora | J11: Tangará da Serra | K11: MT | L11: Madeira | N11: CCA - C | O11: Bagueta | P11: Eucalyptus | Q11: Amostra 02 (8X10) | X11: Mourões | Y11: =IF(X11='Listas suspensas'!$A$21,'Listas suspensas'!$B$23,IF(X11='Listas suspensas'!$A$22,'Listas suspensas'!$B$23,IF(X11='Listas suspensas'!$A$23,'Listas suspensas'!$B$22,IF(X11='Listas suspensas'!$A$26,'Listas suspensas'!$B$22,IF(X11='Listas suspensas'!$A$32,'Listas suspensas'!$B$22,IF(X11='Listas suspensas'!$A$33,'Listas suspensas'!$B$21,IF(X11='Listas suspensas'!$A$24,'Listas suspensas'!$B$22,IF(X11='Listas suspensas'!$A$30,'Listas suspensas'!$B$21,"")))))))) -> 6.5 | Z11: NBR 16143 | AA11: 2 | AB11: =IF(AA11='Listas suspensas'!$A$2,'Listas suspensas'!$B$2,IF(AA11='Listas suspensas'!$A$3,'Listas suspensas'!$B$3,IF(AA11='Listas suspensas'!$A$4,'Listas suspensas'!$B$4,IF(AA11='Listas suspensas'!$A$5,'Listas suspensas'!$B$5,IF(AA11='Listas suspensas'!$A$6,'Listas suspensas'!$B$6,""))))) -> Profunda e irregular | AC11: =IF(AA11='Listas suspensas'!$A$2,'Listas suspensas'!$C$2,IF(AA11='Listas suspensas'!$A$3,'Listas suspensas'!$C$3,IF(AA11='Listas suspensas'!$A$4,'Listas suspensas'!$C$4,IF(AA11='Listas suspensas'!$A$5,'Listas suspensas'!$C$5,IF(AA11='Listas suspensas'!$A$6,'Listas suspensas'!$C$6,""))))) -> Indica a penetração profunda, mas desuniforme em toda a extensão do alburno. | AK11: 11.05 | AL11: 11.37 | AM11: 11.22 | AN11: 11.3 | AO11: 11.23 | AP11: =AVERAGE(AK11:AO11)/10 -> 1.1234 | AQ11: 14.43 | AR11: 14.33 | AS11: 12.59 | AT11: 15.36 | AU11: 13.29 | AV11: =AVERAGE(AQ11:AU11)/10 -> 1.4 | AW11: 1.0486 | AX11: 1.0978 | AY11: 0.9422 | AZ11: 1.1944 | BA11: 1.0293 | BB11: =AVERAGE(AW11:BA11) -> 1.06246 | BC11: =PI()*(AP11/2)^2*AV11 -> 1.3876718 | BE11: =(BB11/BC11)*1000 -> 765.64215 | BF11: 0.419 | BG11: 0.19 | BH11: 0.311 | BI11: =SUM(BF11:BH11) -> 0.92 | BJ11: 45.5 | BK11: 20.7 | BL11: 33.8 | BM11: =ROUND(SUM(BJ11:BL11),2) -> 100 | BN11: =ROUND((BF11/100)*BE11,2) -> 3.21 | BO11: =ROUND((BG11/100)*BE11,2) -> 1.45 | BP11: =ROUND((BH11/100)*BE11,2) -> 2.38 | BQ11: =ROUND(SUM(BN11:BP11),2) -> 7.04 | BR11: =IF(OR(AND(X11="Mourões", BQ11>=6.5),AND(X11="Postes", BQ11>=9.6),AND(X11="Dormentes", BQ11>=9.6),AND(X11="Estacas", BQ11>=6.5),AND(X11="Cruzetas", BQ11>=6.5),AND(X11="Outros - Solo", BQ11>=6.5),AND(X11="Outros - Suspenso",BQ11>=4),AND(X11="Deck",BQ11>=4)),'Listas suspensas'!$C$21,'Listas suspensas'!$C$22) -> Os resultados da análise química apresentaram uma retenção do produto de acordo com o padrão mínimo exigido pela norma ABNT NBR 16143
B12: UFV-M-11 | C12: Finalizada | F12: 45358 | G12: 45358 | H12: 45364 | I12: LiptosFlora | J12: Tangará da Serra | K12: MT | L12: Madeira | N12: CCA - C | O12: Bagueta | P12: Eucalyptus | Q12: Amostra 03 (10x12) | X12: Mourões | Y12: =IF(X12='Listas suspensas'!$A$21,'Listas suspensas'!$B$23,IF(X12='Listas suspensas'!$A$22,'Listas suspensas'!$B$23,IF(X12='Listas suspensas'!$A$23,'Listas suspensas'!$B$22,IF(X12='Listas suspensas'!$A$26,'Listas suspensas'!$B$22,IF(X12='Listas suspensas'!$A$32,'Listas suspensas'!$B$22,IF(X12='Listas suspensas'!$A$33,'Listas suspensas'!$B$21,IF(X12='Listas suspensas'!$A$24,'Listas suspensas'!$B$22,IF(X12='Listas suspensas'!$A$30,'Listas suspensas'!$B$21,"")))))))) -> 6.5 | Z12: NBR 16143 | AA12: 3 | AB12: =IF(AA12='Listas suspensas'!$A$2,'Listas suspensas'!$B$2,IF(AA12='Listas suspensas'!$A$3,'Listas suspensas'!$B$3,IF(AA12='Listas suspensas'!$A$4,'Listas suspensas'!$B$4,IF(AA12='Listas suspensas'!$A$5,'Listas suspensas'!$B$5,IF(AA12='Listas suspensas'!$A$6,'Listas suspensas'!$B$6,""))))) -> Parcial e regular | AC12: =IF(AA12='Listas suspensas'!$A$2,'Listas suspensas'!$C$2,IF(AA12='Listas suspensas'!$A$3,'Listas suspensas'!$C$3,IF(AA12='Listas suspensas'!$A$4,'Listas suspensas'!$C$4,IF(AA12='Listas suspensas'!$A$5,'Listas suspensas'!$C$5,IF(AA12='Listas suspensas'!$A$6,'Listas suspensas'!$C$6,""))))) -> Indica a penetração uniforme, mas não total pela extensão do alburno. | AK12: 11.84 | AL12: 11.38 | AM12: 11.88 | AN12: 11.86 | AO12: 12.14 | AP12: =AVERAGE(AK12:AO12)/10 -> 1.182 | AQ12: 4.51 | AR12: 4.65 | AS12: 5.63 | AT12: 5.29 | AU12: 5.93 | AV12: =AVERAGE(AQ12:AU12)/10 -> 0.5202 | AW12: 0.2882 | AX12: 0.3332 | AY12: 0.3909 | AZ12: 0.3912 | BA12: 0.4418 | BB12: =AVERAGE(AW12:BA12) -> 0.36906 | BC12: =PI()*(AP12/2)^2*AV12 -> 0.57081474 | BE12: =(BB12/BC12)*1000 -> 646.54952 | BI12: =SUM(BF12:BH12) -> 0 | BM12: =ROUND(SUM(BJ12:BL12),2) -> 0 | BN12: =ROUND((BF12/100)*BE12,2) -> 0 | BO12: =ROUND((BG12/100)*BE12,2) -> 0 | BP12: =ROUND((BH12/100)*BE12,2) -> 0 | BQ12: =ROUND(SUM(BN12:BP12),2) -> 0 | BR12: =IF(OR(AND(X12="Mourões", BQ12>=6.5),AND(X12="Postes", BQ12>=9.6),AND(X12="Dormentes", BQ12>=9.6),AND(X12="Estacas", BQ12>=6.5),AND(X12="Cruzetas", BQ12>=6.5),AND(X12="Outros - Solo", BQ12>=6.5),AND(X12="Outros - Suspenso",BQ12>=4),AND(X12="Deck",BQ12>=4)),'Listas suspensas'!$C$21,'Listas suspensas'!$C$22) -> Os resultados da análise química apresentaram uma retenção do produto inferior ao padrão mínimo exigido pela norma ABNT NBR 16143
B13: UFV-M-12 | C13: Finalizada | F13: 45358 | G13: 45358 | H13: 45364 | I13: LiptosFlora | J13: Tangará da Serra | K13: MT | L13: Madeira | N13: CCA - C | O13: Bagueta | P13: Eucalyptus | Q13: Amostra 04 (12x14) | X13: Mourões | Y13: =IF(X13='Listas suspensas'!$A$21,'Listas suspensas'!$B$23,IF(X13='Listas suspensas'!$A$22,'Listas suspensas'!$B$23,IF(X13='Listas suspensas'!$A$23,'Listas suspensas'!$B$22,IF(X13='Listas suspensas'!$A$26,'Listas suspensas'!$B$22,IF(X13='Listas suspensas'!$A$32,'Listas suspensas'!$B$22,IF(X13='Listas suspensas'!$A$33,'Listas suspensas'!$B$21,IF(X13='Listas suspensas'!$A$24,'Listas suspensas'!$B$22,IF(X13='Listas suspensas'!$A$30,'Listas suspensas'!$B$21,"")))))))) -> 6.5 | Z13: NBR 16143 | AA13: 2 | AB13: =IF(AA13='Listas suspensas'!$A$2,'Listas suspensas'!$B$2,IF(AA13='Listas suspensas'!$A$3,'Listas suspensas'!$B$3,IF(AA13='Listas suspensas'!$A$4,'Listas suspensas'!$B$4,IF(AA13='Listas suspensas'!$A$5,'Listas suspensas'!$B$5,IF(AA13='Listas suspensas'!$A$6,'Listas suspensas'!$B$6,""))))) -> Profunda e irregular | AC13: =IF(AA13='Listas suspensas'!$A$2,'Listas suspensas'!$C$2,IF(AA13='Listas suspensas'!$A$3,'Listas suspensas'!$C$3,IF(AA13='Listas suspensas'!$A$4,'Listas suspensas'!$C$4,IF(AA13='Listas suspensas'!$A$5,'Listas suspensas'!$C$5,IF(AA13='Listas suspensas'!$A$6,'Listas suspensas'!$C$6,""))))) -> Indica a penetração profunda, mas desuniforme em toda a extensão do alburno. | AK13: 11.47 | AL13: 11.16 | AM13: 11.94 | AN13: 11.17 | AO13: 11.22 | AP13: =AVERAGE(AK13:AO13)/10 -> 1.1392 | AQ13: 9.2 | AR13: 10.02 | AS13: 9.86 | AT13: 8.33 | AU13: 12.51 | AV13: =AVERAGE(AQ13:AU13)/10 -> 0.9984 | AW13: 0.7724 | AX13: 0.7506 | AY13: 0.7333 | AZ13: 0.6418 | BA13: 0.9759 | BB13: =AVERAGE(AW13:BA13) -> 0.7748 | BC13: =PI()*(AP13/2)^2*AV13 -> 1.0176406 | BE13: =(BB13/BC13)*1000 -> 761.36903 | BF13: 0.327 | BG13: 0.145 | BH13: 0.243 | BI13: =SUM(BF13:BH13) -> 0.715 | BJ13: 45.7 | BK13: 20.3 | BL13: 34 | BM13: =ROUND(SUM(BJ13:BL13),2) -> 100 | BN13: =ROUND((BF13/100)*BE13,2) -> 2.49 | BO13: =ROUND((BG13/100)*BE13,2) -> 1.1 | BP13: =ROUND((BH13/100)*BE13,2) -> 1.85 | BQ13: =ROUND(SUM(BN13:BP13),2) -> 5.44 | BR13: =IF(OR(AND(X13="Mourões", BQ13>=6.5),AND(X13="Postes", BQ13>=9.6),AND(X13="Dormentes", BQ13>=9.6),AND(X13="Estacas", BQ13>=6.5),AND(X13="Cruzetas", BQ13>=6.5),AND(X13="Outros - Solo", BQ13>=6.5),AND(X13="Outros - Suspenso",BQ13>=4),AND(X13="Deck",BQ13>=4)),'Listas suspensas'!$C$21,'Listas suspensas'!$C$22) -> Os resultados da análise química apresentaram uma retenção do produto inferior ao padrão mínimo exigido pela norma ABNT NBR 16143
B14: UFV-M-13 | C14: Finalizada | F14: 45358 | G14: 45358 | H14: 45364 | I14: LiptosFlora | J14: Tangará da Serra | K14: MT | L14: Madeira | N14: CCA - C | O14: Bagueta | P14: Eucalyptus | Q14: Amostra 05 (10x12) | X14: Mourões | Y14: =IF(X14='Listas suspensas'!$A$21,'Listas suspensas'!$B$23,IF(X14='Listas suspensas'!$A$22,'Listas suspensas'!$B$23,IF(X14='Listas suspensas'!$A$23,'Listas suspensas'!$B$22,IF(X14='Listas suspensas'!$A$26,'Listas suspensas'!$B$22,IF(X14='Listas suspensas'!$A$32,'Listas suspensas'!$B$22,IF(X14='Listas suspensas'!$A$33,'Listas suspensas'!$B$21,IF(X14='Listas suspensas'!$A$24,'Listas suspensas'!$B$22,IF(X14='Listas suspensas'!$A$30,'Listas suspensas'!$B$21,"")))))))) -> 6.5 | Z14: NBR 16143 | AA14: 3 | AB14: =IF(AA14='Listas suspensas'!$A$2,'Listas suspensas'!$B$2,IF(AA14='Listas suspensas'!$A$3,'Listas suspensas'!$B$3,IF(AA14='Listas suspensas'!$A$4,'Listas suspensas'!$B$4,IF(AA14='Listas suspensas'!$A$5,'Listas suspensas'!$B$5,IF(AA14='Listas suspensas'!$A$6,'Listas suspensas'!$B$6,""))))) -> Parcial e regular | AC14: =IF(AA14='Listas suspensas'!$A$2,'Listas suspensas'!$C$2,IF(AA14='Listas suspensas'!$A$3,'Listas suspensas'!$C$3,IF(AA14='Listas suspensas'!$A$4,'Listas suspensas'!$C$4,IF(AA14='Listas suspensas'!$A$5,'Listas suspensas'!$C$5,IF(AA14='Listas suspensas'!$A$6,'Listas suspensas'!$C$6,""))))) -> Indica a penetração uniforme, mas não total pela extensão do alburno. | AK14: 11.14 | AL14: 11.4 | AM14: 11.41 | AN14: 11.1 | AO14: 11.1 | AP14: =AVERAGE(AK14:AO14)/10 -> 1.123 | AQ14: 9.93 | AR14: 9.62 | AS14: 9.03 | AT14: 8 | AU14: 8.12 | AV14: =AVERAGE(AQ14:AU14)/10 -> 0.894 | AW14: 0.8105 | AX14: 0.8205 | AY14: 0.7324 | AZ14: 0.6016 | BA14: 0.6706 | BB14: =AVERAGE(AW14:BA14) -> 0.72712 | BC14: =PI()*(AP14/2)^2*AV14 -> 0.88549663 | BE14: =(BB14/BC14)*1000 -> 821.14372 | BF14: 0.291 | BG14: 0.115 | BH14: 0.172 | BI14: =SUM(BF14:BH14) -> 0.578 | BJ14: 50.4 | BK14: 19.8 | BL14: 29.8 | BM14: =ROUND(SUM(BJ14:BL14),2) -> 100 | BN14: =ROUND((BF14/100)*BE14,2) -> 2.39 | BO14: =ROUND((BG14/100)*BE14,2) -> 0.94 | BP14: =ROUND((BH14/100)*BE14,2) -> 1.41 | BQ14: =ROUND(SUM(BN14:BP14),2) -> 4.74 | BR14: =IF(OR(AND(X14="Mourões", BQ14>=6.5),AND(X14="Postes", BQ14>=9.6),AND(X14="Dormentes", BQ14>=9.6),AND(X14="Estacas", BQ14>=6.5),AND(X14="Cruzetas", BQ14>=6.5),AND(X14="Outros - Solo", BQ14>=6.5),AND(X14="Outros - Suspenso",BQ14>=4),AND(X14="Deck",BQ14>=4)),'Listas suspensas'!$C$21,'Listas suspensas'!$C$22) -> Os resultados da análise química apresentaram uma retenção do produto inferior ao padrão mínimo exigido pela norma ABNT NBR 16143
B15: UFV-M-14 | C15: Finalizada | F15: 45358 | G15: 45358 | H15: 45364 | I15: LiptosFlora | J15: Tangará da Serra | K15: MT | L15: Madeira | N15: CCA - C | O15: Bagueta | P15: Eucalyptus | Q15: Amostra 06 (15x18) | X15: Mourões | Y15: =IF(X15='Listas suspensas'!$A$21,'Listas suspensas'!$B$23,IF(X15='Listas suspensas'!$A$22,'Listas suspensas'!$B$23,IF(X15='Listas suspensas'!$A$23,'Listas suspensas'!$B$22,IF(X15='Listas suspensas'!$A$26,'Listas suspensas'!$B$22,IF(X15='Listas suspensas'!$A$32,'Listas suspensas'!$B$22,IF(X15='Listas suspensas'!$A$33,'Listas suspensas'!$B$21,IF(X15='Listas suspensas'!$A$24,'Listas suspensas'!$B$22,IF(X15='Listas suspensas'!$A$30,'Listas suspensas'!$B$21,"")))))))) -> 6.5 | Z15: NBR 16143 | AA15: 4 | AB15: =IF(AA15='Listas suspensas'!$A$2,'Listas suspensas'!$B$2,IF(AA15='Listas suspensas'!$A$3,'Listas suspensas'!$B$3,IF(AA15='Listas suspensas'!$A$4,'Listas suspensas'!$B$4,IF(AA15='Listas suspensas'!$A$5,'Listas suspensas'!$B$5,IF(AA15='Listas suspensas'!$A$6,'Listas suspensas'!$B$6,""))))) -> Parcial e irregular | AC15: =IF(AA15='Listas suspensas'!$A$2,'Listas suspensas'!$C$2,IF(AA15='Listas suspensas'!$A$3,'Listas suspensas'!$C$3,IF(AA15='Listas suspensas'!$A$4,'Listas suspensas'!$C$4,IF(AA15='Listas suspensas'!$A$5,'Listas suspensas'!$C$5,IF(AA15='Listas suspensas'!$A$6,'Listas suspensas'!$C$6,""))))) -> Indica a penetração desuniforme e não total pela extensão do alburno. | AK15: 11.08 | AL15: 11.13 | AM15: 11.12 | AN15: 11.23 | AO15: 11.17 | AP15: =AVERAGE(AK15:AO15)/10 -> 1.1146 | AQ15: 12.5 | AR15: 12.52 | AS15: 12.51 | AT15: 11.21 | AU15: 11.13 | AV15: =AVERAGE(AQ15:AU15)/10 -> 1.1974 | AW15: 1.1462 | AX15: 1.1811 | AY15: 1.2063 | AZ15: 1.0026 | BA15: 1.0388 | BB15: =AVERAGE(AW15:BA15) -> 1.115 | BC15: =PI()*(AP15/2)^2*AV15 -> 1.1683345 | BE15: =(BB15/BC15)*1000 -> 954.34995 | BF15: 0.282 | BG15: 0.122 | BH15: 0.209 | BI15: =SUM(BF15:BH15) -> 0.613 | BJ15: 46 | BK15: 19.9 | BL15: 34.1 | BM15: =ROUND(SUM(BJ15:BL15),2) -> 100 | BN15: =ROUND((BF15/100)*BE15,2) -> 2.69 | BO15: =ROUND((BG15/100)*BE15,2) -> 1.16 | BP15: =ROUND((BH15/100)*BE15,2) -> 1.99 | BQ15: =ROUND(SUM(BN15:BP15),2) -> 5.84 | BR15: =IF(OR(AND(X15="Mourões", BQ15>=6.5),AND(X15="Postes", BQ15>=9.6),AND(X15="Dormentes", BQ15>=9.6),AND(X15="Estacas", BQ15>=6.5),AND(X15="Cruzetas", BQ15>=6.5),AND(X15="Outros - Solo", BQ15>=6.5),AND(X15="Outros - Suspenso",BQ15>=4),AND(X15="Deck",BQ15>=4)),'Listas suspensas'!$C$21,'Listas suspensas'!$C$22) -> Os resultados da análise química apresentaram uma retenção do produto inferior ao padrão mínimo exigido pela norma ABNT NBR 16143
B16: UFV-M-15 | C16: Finalizada | F16: 45358 | G16: 45358 | H16: 45364 | I16: LiptosFlora | J16: Tangará da Serra | K16: MT | L16: Madeira | N16: CCA - C | O16: Bagueta | P16: Eucalyptus | Q16: Amostra 07 (13x15) | X16: Mourões | Y16: =IF(X16='Listas suspensas'!$A$21,'Listas suspensas'!$B$23,IF(X16='Listas suspensas'!$A$22,'Listas suspensas'!$B$23,IF(X16='Listas suspensas'!$A$23,'Listas suspensas'!$B$22,IF(X16='Listas suspensas'!$A$26,'Listas suspensas'!$B$22,IF(X16='Listas suspensas'!$A$32,'Listas suspensas'!$B$22,IF(X16='Listas suspensas'!$A$33,'Listas suspensas'!$B$21,IF(X16='Listas suspensas'!$A$24,'Listas suspensas'!$B$22,IF(X16='Listas suspensas'!$A$30,'Listas suspensas'!$B$21,"")))))))) -> 6.5 | Z16: NBR 16143 | AA16: 4 | AB16: =IF(AA16='Listas suspensas'!$A$2,'Listas suspensas'!$B$2,IF(AA16='Listas suspensas'!$A$3,'Listas suspensas'!$B$3,IF(AA16='Listas suspensas'!$A$4,'Listas suspensas'!$B$4,IF(AA16='Listas suspensas'!$A$5,'Listas suspensas'!$B$5,IF(AA16='Listas suspensas'!$A$6,'Listas suspensas'!$B$6,""))))) -> Parcial e irregular | AC16: =IF(AA16='Listas suspensas'!$A$2,'Listas suspensas'!$C$2,IF(AA16='Listas suspensas'!$A$3,'Listas suspensas'!$C$3,IF(AA16='Listas suspensas'!$A$4,'Listas suspensas'!$C$4,IF(AA16='Listas suspensas'!$A$5,'Listas suspensas'!$C$5,IF(AA16='Listas suspensas'!$A$6,'Listas suspensas'!$C$6,""))))) -> Indica a penetração desuniforme e não total pela extensão do alburno. | AK16: 11.04 | AL16: 10.9 | AM16: 11.95 | AN16: 11.07 | AO16: 11.09 | AP16: =AVERAGE(AK16:AO16)/10 -> 1.121 | AQ16: 8.52 | AR16: 11.99 | AS16: 10.09 | AT16: 11.23 | AU16: 9.07 | AV16: =AVERAGE(AQ16:AU16)/10 -> 1.018 | AW16: 0.8111 | AX16: 1.0545 | AY16: 0.9687 | AZ16: 1.0774 | BA16: 0.8391 | BB16: =AVERAGE(AW16:BA16) -> 0.95016 | BC16: =PI()*(AP16/2)^2*AV16 -> 1.0047289 | BE16: =(BB16/BC16)*1000 -> 945.68796 | BF16: 0.261 | BG16: 0.107 | BH16: 0.193 | BI16: =SUM(BF16:BH16) -> 0.561 | BJ16: 46.5 | BK16: 19.1 | BL16: 34.4 | BM16: =ROUND(SUM(BJ16:BL16),2) -> 100 | BN16: =ROUND((BF16/100)*BE16,2) -> 2.47 | BO16: =ROUND((BG16/100)*BE16,2) -> 1.01 | BP16: =ROUND((BH16/100)*BE16,2) -> 1.83 | BQ16: =ROUND(SUM(BN16:BP16),2) -> 5.31 | BR16: =IF(OR(AND(X16="Mourões", BQ16>=6.5),AND(X16="Postes", BQ16>=9.6),AND(X16="Dormentes", BQ16>=9.6),AND(X16="Estacas", BQ16>=6.5),AND(X16="Cruzetas", BQ16>=6.5),AND(X16="Outros - Solo", BQ16>=6.5),AND(X16="Outros - Suspenso",BQ16>=4),AND(X16="Deck",BQ16>=4)),'Listas suspensas'!$C$21,'Listas suspensas'!$C$22) -> Os resultados da análise química apresentaram uma retenção do produto inferior ao padrão mínimo exigido pela norma ABNT NBR 16143
B17: UFV-M-16 | C17: Finalizada | F17: 45358 | G17: 45358 | H17: 45364 | I17: LiptosFlora | J17: Tangará da Serra | K17: MT | L17: Madeira | N17: CCA - C | O17: Bagueta | P17: Corymbia | Q17: Amostra 08 (Citriodoro) | X17: Mourões | Y17: =IF(X17='Listas suspensas'!$A$21,'Listas suspensas'!$B$23,IF(X17='Listas suspensas'!$A$22,'Listas suspensas'!$B$23,IF(X17='Listas suspensas'!$A$23,'Listas suspensas'!$B$22,IF(X17='Listas suspensas'!$A$26,'Listas suspensas'!$B$22,IF(X17='Listas suspensas'!$A$32,'Listas suspensas'!$B$22,IF(X17='Listas suspensas'!$A$33,'Listas suspensas'!$B$21,IF(X17='Listas suspensas'!$A$24,'Listas suspensas'!$B$22,IF(X17='Listas suspensas'!$A$30,'Listas suspensas'!$B$21,"")))))))) -> 6.5 | Z17: NBR 16143 | AA17: 1 | AB17: =IF(AA17='Listas suspensas'!$A$2,'Listas suspensas'!$B$2,IF(AA17='Listas suspensas'!$A$3,'Listas suspensas'!$B$3,IF(AA17='Listas suspensas'!$A$4,'Listas suspensas'!$B$4,IF(AA17='Listas suspensas'!$A$5,'Listas suspensas'!$B$5,IF(AA17='Listas suspensas'!$A$6,'Listas suspensas'!$B$6,""))))) -> Profunda e regular | AC17: =IF(AA17='Listas suspensas'!$A$2,'Listas suspensas'!$C$2,IF(AA17='Listas suspensas'!$A$3,'Listas suspensas'!$C$3,IF(AA17='Listas suspensas'!$A$4,'Listas suspensas'!$C$4,IF(AA17='Listas suspensas'!$A$5,'Listas suspensas'!$C$5,IF(AA17='Listas suspensas'!$A$6,'Listas suspensas'!$C$6,""))))) -> Indica a penetração profunda e uniforme em toda a extensão do alburno. | AK17: 11.43 | AL17: 11.24 | AM17: 11.18 | AN17: 11.43 | AO17: 11.18 | AP17: =AVERAGE(AK17:AO17)/10 -> 1.1292 | AQ17: 23.16 | AR17: 24.9 | AS17: 20.4 | AT17: 29.51 | AU17: 34.1 | AV17: =AVERAGE(AQ17:AU17)/10 -> 2.6414 | AW17: 2.0496 | AX17: 1.8898 | AY17: 1.79 | AZ17: 2.5661 | BA17: 2.9373 | BB17: =AVERAGE(AW17:BA17) -> 2.24656 | BC17: =PI()*(AP17/2)^2*AV17 -> 2.6452443 | BE17: =(BB17/BC17)*1000 -> 849.2826 | BF17: 0.308 | BG17: 0.206 | BH17: 0.375 | BI17: =SUM(BF17:BH17) -> 0.889 | BJ17: 34.6 | BK17: 23.2 | BL17: 42.2 | BM17: =ROUND(SUM(BJ17:BL17),2) -> 100 | BN17: =ROUND((BF17/100)*BE17,2) -> 2.62 | BO17: =ROUND((BG17/100)*BE17,2) -> 1.75 | BP17: =ROUND((BH17/100)*BE17,2) -> 3.18 | BQ17: =ROUND(SUM(BN17:BP17),2) -> 7.55 | BR17: =IF(OR(AND(X17="Mourões", BQ17>=6.5),AND(X17="Postes", BQ17>=9.6),AND(X17="Dormentes", BQ17>=9.6),AND(X17="Estacas", BQ17>=6.5),AND(X17="Cruzetas", BQ17>=6.5),AND(X17="Outros - Solo", BQ17>=6.5),AND(X17="Outros - Suspenso",BQ17>=4),AND(X17="Deck",BQ17>=4)),'Listas suspensas'!$C$21,'Listas suspensas'!$C$22) -> Os resultados da análise química apresentaram uma retenção do produto de acordo com o padrão mínimo exigido pela norma ABNT NBR 16143
B18: UFV-M-17 | C18: Finalizada | F18: 45358 | G18: 45358 | H18: 45364 | I18: LiptosFlora | J18: Tangará da Serra | K18: MT | L18: Madeira | N18: CCA - C | O18: Bagueta | P18: Corymbia | Q18: Amostra 09 (Citriodoro) | X18: Mourões | Y18: =IF(X18='Listas suspensas'!$A$21,'Listas suspensas'!$B$23,IF(X18='Listas suspensas'!$A$22,'Listas suspensas'!$B$23,IF(X18='Listas suspensas'!$A$23,'Listas suspensas'!$B$22,IF(X18='Listas suspensas'!$A$26,'Listas suspensas'!$B$22,IF(X18='Listas suspensas'!$A$32,'Listas suspensas'!$B$22,IF(X18='Listas suspensas'!$A$33,'Listas suspensas'!$B$21,IF(X18='Listas suspensas'!$A$24,'Listas suspensas'!$B$22,IF(X18='Listas suspensas'!$A$30,'Listas suspensas'!$B$21,"")))))))) -> 6.5 | Z18: NBR 16143 | AA18: 1 | AB18: =IF(AA18='Listas suspensas'!$A$2,'Listas suspensas'!$B$2,IF(AA18='Listas suspensas'!$A$3,'Listas suspensas'!$B$3,IF(AA18='Listas suspensas'!$A$4,'Listas suspensas'!$B$4,IF(AA18='Listas suspensas'!$A$5,'Listas suspensas'!$B$5,IF(AA18='Listas suspensas'!$A$6,'Listas suspensas'!$B$6,""))))) -> Profunda e regular | AC18: =IF(AA18='Listas suspensas'!$A$2,'Listas suspensas'!$C$2,IF(AA18='Listas suspensas'!$A$3,'Listas suspensas'!$C$3,IF(AA18='Listas suspensas'!$A$4,'Listas suspensas'!$C$4,IF(AA18='Listas suspensas'!$A$5,'Listas suspensas'!$C$5,IF(AA18='Listas suspensas'!$A$6,'Listas suspensas'!$C$6,""))))) -> Indica a penetração profunda e uniforme em toda a extensão do alburno. | AK18: 11.31 | AL18: 11.17 | AM18: 11.74 | AN18: 11.44 | AO18: 11.38 | AP18: =AVERAGE(AK18:AO18)/10 -> 1.1408 | AQ18: 26.45 | AR18: 29.43 | AS18: 22.21 | AT18: 26.87 | AU18: 32.67 | AV18: =AVERAGE(AQ18:AU18)/10 -> 2.7526 | AW18: 2.179 | AX18: 2.431 | AY18: 1.727 | AZ18: 2.1584 | BA18: 2.6178 | BB18: =AVERAGE(AW18:BA18) -> 2.22264 | BC18: =PI()*(AP18/2)^2*AV18 -> 2.813533 | BE18: =(BB18/BC18)*1000 -> 789.98185 | BF18: 0.336 | BG18: 0.219 | BH18: 0.411 | BI18: =SUM(BF18:BH18) -> 0.966 | BJ18: 34.8 | BK18: 22.7 | BL18: 42.5 | BM18: =ROUND(SUM(BJ18:BL18),2) -> 100 | BN18: =ROUND((BF18/100)*BE18,2) -> 2.65 | BO18: =ROUND((BG18/100)*BE18,2) -> 1.73 | BP18: =ROUND((BH18/100)*BE18,2) -> 3.25 | BQ18: =ROUND(SUM(BN18:BP18),2) -> 7.63 | BR18: =IF(OR(AND(X18="Mourões", BQ18>=6.5),AND(X18="Postes", BQ18>=9.6),AND(X18="Dormentes", BQ18>=9.6),AND(X18="Estacas", BQ18>=6.5),AND(X18="Cruzetas", BQ18>=6.5),AND(X18="Outros - Solo", BQ18>=6.5),AND(X18="Outros - Suspenso",BQ18>=4),AND(X18="Deck",BQ18>=4)),'Listas suspensas'!$C$21,'Listas suspensas'!$C$22) -> Os resultados da análise química apresentaram uma retenção do produto de acordo com o padrão mínimo exigido pela norma ABNT NBR 16143
A19: 54888 | B19: UFV-M-18 | C19: Finalizada | D19: 39.861.262/0001-86 | F19: 45370 | G19: 45370 | H19: 45373 | I19: SC Madeiras LTDA | J19: Olhos D'Água | K19: MG | L19: Madeira | M19: scmadeira21@gmail.com | N19: CCA - C | O19: Torete | P19: Eucalyptus | Q19: Amostra 2 - 14x16 - 4,0 | X19: Mourões | Y19: =IF(X19='Listas suspensas'!$A$21,'Listas suspensas'!$B$23,IF(X19='Listas suspensas'!$A$22,'Listas suspensas'!$B$23,IF(X19='Listas suspensas'!$A$23,'Listas suspensas'!$B$22,IF(X19='Listas suspensas'!$A$26,'Listas suspensas'!$B$22,IF(X19='Listas suspensas'!$A$32,'Listas suspensas'!$B$22,IF(X19='Listas suspensas'!$A$33,'Listas suspensas'!$B$21,IF(X19='Listas suspensas'!$A$24,'Listas suspensas'!$B$22,IF(X19='Listas suspensas'!$A$30,'Listas suspensas'!$B$21,"")))))))) -> 6.5 | Z19: NBR 16143 | AA19: 4 | AB19: =IF(AA19='Listas suspensas'!$A$2,'Listas suspensas'!$B$2,IF(AA19='Listas suspensas'!$A$3,'Listas suspensas'!$B$3,IF(AA19='Listas suspensas'!$A$4,'Listas suspensas'!$B$4,IF(AA19='Listas suspensas'!$A$5,'Listas suspensas'!$B$5,IF(AA19='Listas suspensas'!$A$6,'Listas suspensas'!$B$6,""))))) -> Parcial e irregular | AC19: =IF(AA19='Listas suspensas'!$A$2,'Listas suspensas'!$C$2,IF(AA19='Listas suspensas'!$A$3,'Listas suspensas'!$C$3,IF(AA19='Listas suspensas'!$A$4,'Listas suspensas'!$C$4,IF(AA19='Listas suspensas'!$A$5,'Listas suspensas'!$C$5,IF(AA19='Listas suspensas'!$A$6,'Listas suspensas'!$C$6,""))))) -> Indica a penetração desuniforme e não total pela extensão do alburno. | AK19: 11.42 | AL19: 11.56 | AM19: 11.57 | AN19: 11.25 | AO19: 11.5 | AP19: =AVERAGE(AK19:AO19)/10 -> 1.146 | AQ19: 11.68 | AR19: 11.42 | AS19: 12.34 | AT19: 11.44 | AU19: 13.66 | AV19: =AVERAGE(AQ19:AU19)/10 -> 1.2108 | AW19: 1.0616 | AX19: 1.0277 | AY19: 1.112 | AZ19: 0.9603 | BA19: 1.198 | BB19: =AVERAGE(AW19:BA19) -> 1.07192 | BC19: =PI()*(AP19/2)^2*AV19 -> 1.2489111 | BE19: =(BB19/BC19)*1000 -> 858.28366 | BF19: 0.152 | BG19: 0.068 | BH19: 0.101 | BI19: =SUM(BF19:BH19) -> 0.321 | BJ19: 47.4 | BK19: 21.2 | BL19: 31.4 | BM19: =ROUND(SUM(BJ19:BL19),2) -> 100 | BN19: =ROUND((BF19/100)*BE19,2) -> 1.3 | BO19: =ROUND((BG19/100)*BE19,2) -> 0.58 | BP19: =ROUND((BH19/100)*BE19,2) -> 0.87 | BQ19: =ROUND(SUM(BN19:BP19),2) -> 2.75 | BR19: =IF(OR(AND(X19="Mourões", BQ19>=6.5),AND(X19="Postes", BQ19>=9.6),AND(X19="Dormentes", BQ19>=9.6),AND(X19="Estacas", BQ19>=6.5),AND(X19="Cruzetas", BQ19>=6.5),AND(X19="Outros - Solo", BQ19>=6.5),AND(X19="Outros - Suspenso",BQ19>=4),AND(X19="Deck",BQ19>=4)),'Listas suspensas'!$C$21,'Listas suspensas'!$C$22) -> Os resultados da análise química apresentaram uma retenção do produto inferior ao padrão mínimo exigido pela norma ABNT NBR 16143
A20: 54888 | B20: UFV-M-19 | C20: Finalizada | D20: 39.861.262/0001-86 | F20: 45370 | G20: 45370 | H20: 45376 | I20: SC Madeiras LTDA | J20: Olhos D'Água | K20: MG | L20: Madeira | M20: scmadeira21@gmail.com | N20: CCA - C | O20: Torete | P20: Eucalyptus | Q20: Amostra 3 - 08x10 - 3,0m | X20: Mourões | Y20: =IF(X20='Listas suspensas'!$A$21,'Listas suspensas'!$B$23,IF(X20='Listas suspensas'!$A$22,'Listas suspensas'!$B$23,IF(X20='Listas suspensas'!$A$23,'Listas suspensas'!$B$22,IF(X20='Listas suspensas'!$A$26,'Listas suspensas'!$B$22,IF(X20='Listas suspensas'!$A$32,'Listas suspensas'!$B$22,IF(X20='Listas suspensas'!$A$33,'Listas suspensas'!$B$21,IF(X20='Listas suspensas'!$A$24,'Listas suspensas'!$B$22,IF(X20='Listas suspensas'!$A$30,'Listas suspensas'!$B$21,"")))))))) -> 6.5 | Z20: NBR 16143 | AA20: 2 | AB20: =IF(AA20='Listas suspensas'!$A$2,'Listas suspensas'!$B$2,IF(AA20='Listas suspensas'!$A$3,'Listas suspensas'!$B$3,IF(AA20='Listas suspensas'!$A$4,'Listas suspensas'!$B$4,IF(AA20='Listas suspensas'!$A$5,'Listas suspensas'!$B$5,IF(AA20='Listas suspensas'!$A$6,'Listas suspensas'!$B$6,""))))) -> Profunda e irregular | AC20: =IF(AA20='Listas suspensas'!$A$2,'Listas suspensas'!$C$2,IF(AA20='Listas suspensas'!$A$3,'Listas suspensas'!$C$3,IF(AA20='Listas suspensas'!$A$4,'Listas suspensas'!$C$4,IF(AA20='Listas suspensas'!$A$5,'Listas suspensas'!$C$5,IF(AA20='Listas suspensas'!$A$6,'Listas suspensas'!$C$6,""))))) -> Indica a penetração profunda, mas desuniforme em toda a extensão do alburno. | AK20: 11.54 | AL20: 11.44 | AM20: 11.6 | AN20: 11.7 | AO20: 11.2 | AP20: =AVERAGE(AK20:AO20)/10 -> 1.1496 | AQ20: 9.83 | AR20: 9.73 | AS20: 8.79 | AT20: 11.33 | AU20: 8.58 | AV20: =AVERAGE(AQ20:AU20)/10 -> 0.9652 | AW20: 0.743 | AX20: 0.7391 | AY20: 0.6841 | AZ20: 0.9109 | BA20: 0.6995 | BB20: =AVERAGE(AW20:BA20) -> 0.75532 | BC20: =PI()*(AP20/2)^2*AV20 -> 1.0018454 | BE20: =(BB20/BC20)*1000 -> 753.92871 | BF20: 0.241 | BG20: 0.123 | BH20: 0.215 | BI20: =SUM(BF20:BH20) -> 0.579 | BJ20: 41.7 | BK20: 21.2 | BL20: 37.1 | BM20: =ROUND(SUM(BJ20:BL20),2) -> 100 | BN20: =ROUND((BF20/100)*BE20,2) -> 1.82 | BO20: =ROUND((BG20/100)*BE20,2) -> 0.93 | BP20: =ROUND((BH20/100)*BE20,2) -> 1.62 | BQ20: =ROUND(SUM(BN20:BP20),2) -> 4.37 | BR20: =IF(OR(AND(X20="Mourões", BQ20>=6.5),AND(X20="Postes", BQ20>=9.6),AND(X20="Dormentes", BQ20>=9.6),AND(X20="Estacas", BQ20>=6.5),AND(X20="Cruzetas", BQ20>=6.5),AND(X20="Outros - Solo", BQ20>=6.5),AND(X20="Outros - Suspenso",BQ20>=4),AND(X20="Deck",BQ20>=4)),'Listas suspensas'!$C$21,'Listas suspensas'!$C$22) -> Os resultados da análise química apresentaram uma retenção do produto inferior ao padrão mínimo exigido pela norma ABNT NBR 16143
A21: 54888 | B21: UFV-M-20 | C21: Finalizada | D21: 39.861.262/0001-86 | F21: 45370 | G21: 45370 | H21: 45376 | I21: SC Madeiras LTDA | J21: Olhos D'Água | K21: MG | L21: Madeira | M21: scmadeira21@gmail.com | N21: CCA - C | O21: Torete | P21: Eucalyptus | Q21: Amostra 4 - 12x14 - 8,0m | X21: Mourões | Y21: =IF(X21='Listas suspensas'!$A$21,'Listas suspensas'!$B$23,IF(X21='Listas suspensas'!$A$22,'Listas suspensas'!$B$23,IF(X21='Listas suspensas'!$A$23,'Listas suspensas'!$B$22,IF(X21='Listas suspensas'!$A$26,'Listas suspensas'!$B$22,IF(X21='Listas suspensas'!$A$32,'Listas suspensas'!$B$22,IF(X21='Listas suspensas'!$A$33,'Listas suspensas'!$B$21,IF(X21='Listas suspensas'!$A$24,'Listas suspensas'!$B$22,IF(X21='Listas suspensas'!$A$30,'Listas suspensas'!$B$21,"")))))))) -> 6.5 | Z21: NBR 16143 | AA21: 2 | AB21: =IF(AA21='Listas suspensas'!$A$2,'Listas suspensas'!$B$2,IF(AA21='Listas suspensas'!$A$3,'Listas suspensas'!$B$3,IF(AA21='Listas suspensas'!$A$4,'Listas suspensas'!$B$4,IF(AA21='Listas suspensas'!$A$5,'Listas suspensas'!$B$5,IF(AA21='Listas suspensas'!$A$6,'Listas suspensas'!$B$6,""))))) -> Profunda e irregular | AC21: =IF(AA21='Listas suspensas'!$A$2,'Listas suspensas'!$C$2,IF(AA21='Listas suspensas'!$A$3,'Listas suspensas'!$C$3,IF(AA21='Listas suspensas'!$A$4,'Listas suspensas'!$C$4,IF(AA21='Listas suspensas'!$A$5,'Listas suspensas'!$C$5,IF(AA21='Listas suspensas'!$A$6,'Listas suspensas'!$C$6,""))))) -> Indica a penetração profunda, mas desuniforme em toda a extensão do alburno. | AK21: 11.25 | AL21: 11.36 | AM21: 11.35 | AN21: 11.38 | AO21: 11.37 | AP21: =AVERAGE(AK21:AO21)/10 -> 1.1342 | AQ21: 8.36 | AR21: 6.41 | AS21: 7.23 | AT21: 9.96 | AU21: 10.84 | AV21: =AVERAGE(AQ21:AU21)/10 -> 0.856 | AW21: 0.6146 | AX21: 0.5056 | AY21: 0.5582 | AZ21: 0.804 | BA21: 0.8768 | BB21: =AVERAGE(AW21:BA21) -> 0.67184 | BC21: =PI()*(AP21/2)^2*AV21 -> 0.86485427 | BE21: =(BB21/BC21)*1000 -> 776.82452 | BF21: 0.261 | BG21: 0.125 | BH21: 0.222 | BI21: =SUM(BF21:BH21) -> 0.608 | BJ21: 43 | BK21: 20.5 | BL21: 36.5 | BM21: =ROUND(SUM(BJ21:BL21),2) -> 100 | BN21: =ROUND((BF21/100)*BE21,2) -> 2.03 | BO21: =ROUND((BG21/100)*BE21,2) -> 0.97 | BP21: =ROUND((BH21/100)*BE21,2) -> 1.72 | BQ21: =ROUND(SUM(BN21:BP21),2) -> 4.72 | BR21: =IF(OR(AND(X21="Mourões", BQ21>=6.5),AND(X21="Postes", BQ21>=9.6),AND(X21="Dormentes", BQ21>=9.6),AND(X21="Estacas", BQ21>=6.5),AND(X21="Cruzetas", BQ21>=6.5),AND(X21="Outros - Solo", BQ21>=6.5),AND(X21="Outros - Suspenso",BQ21>=4),AND(X21="Deck",BQ21>=4)),'Listas suspensas'!$C$21,'Listas suspensas'!$C$22) -> Os resultados da análise química apresentaram uma retenção do produto inferior ao padrão mínimo exigido pela norma ABNT NBR 16143
B22: UFV-M-21 | C22: Finalizada | D22: 03.676.002/0001-93 | F22: 45371 | G22: 45372 | H22: 45376 | I22: Madtrat | J22: Santa Cruz do Rio Pardo | K22: SP | L22: Madeira | M22: qualidade@madtrat.com.br | N22: CCA - C | O22: Bagueta | P22: E. urophylla | Q22: VCS0002 | X22: Mourões | Y22: =IF(X22='Listas suspensas'!$A$21,'Listas suspensas'!$B$23,IF(X22='Listas suspensas'!$A$22,'Listas suspensas'!$B$23,IF(X22='Listas suspensas'!$A$23,'Listas suspensas'!$B$22,IF(X22='Listas suspensas'!$A$26,'Listas suspensas'!$B$22,IF(X22='Listas suspensas'!$A$32,'Listas suspensas'!$B$22,IF(X22='Listas suspensas'!$A$33,'Listas suspensas'!$B$21,IF(X22='Listas suspensas'!$A$24,'Listas suspensas'!$B$22,IF(X22='Listas suspensas'!$A$30,'Listas suspensas'!$B$21,"")))))))) -> 6.5 | Z22: NBR 16143 | AA22: 1 | AB22: =IF(AA22='Listas suspensas'!$A$2,'Listas suspensas'!$B$2,IF(AA22='Listas suspensas'!$A$3,'Listas suspensas'!$B$3,IF(AA22='Listas suspensas'!$A$4,'Listas suspensas'!$B$4,IF(AA22='Listas suspensas'!$A$5,'Listas suspensas'!$B$5,IF(AA22='Listas suspensas'!$A$6,'Listas suspensas'!$B$6,""))))) -> Profunda e regular | AC22: =IF(AA22='Listas suspensas'!$A$2,'Listas suspensas'!$C$2,IF(AA22='Listas suspensas'!$A$3,'Listas suspensas'!$C$3,IF(AA22='Listas suspensas'!$A$4,'Listas suspensas'!$C$4,IF(AA22='Listas suspensas'!$A$5,'Listas suspensas'!$C$5,IF(AA22='Listas suspensas'!$A$6,'Listas suspensas'!$C$6,""))))) -> Indica a penetração profunda e uniforme em toda a extensão do alburno. | AK22: 11.07 | AL22: 11.12 | AM22: 11.83 | AN22: 10.89 | AO22: 11.03 | AP22: =AVERAGE(AK22:AO22)/10 -> 1.1188 | AQ22: 21.54 | AR22: 21.85 | AS22: 26.06 | AT22: 21.06 | AU22: 21.29 | AV22: =AVERAGE(AQ22:AU22)/10 -> 2.236 | AW22: 1.9721 | AX22: 2.0097 | AY22: 2.4729 | AZ22: 1.9235 | BA22: 1.9341 | BB22: =AVERAGE(AW22:BA22) -> 2.06246 | BC22: =PI()*(AP22/2)^2*AV22 -> 2.1981969 | BE22: =(BB22/BC22)*1000 -> 938.25079 | BF22: 0.248 | BG22: 0.129 | BH22: 0.264 | BI22: =SUM(BF22:BH22) -> 0.641 | BJ22: 38.7 | BK22: 20.2 | BL22: 41.1 | BM22: =ROUND(SUM(BJ22:BL22),2) -> 100 | BN22: =ROUND((BF22/100)*BE22,2) -> 2.33 | BO22: =ROUND((BG22/100)*BE22,2) -> 1.21 | BP22: =ROUND((BH22/100)*BE22,2) -> 2.48 | BQ22: =ROUND(SUM(BN22:BP22),2) -> 6.02 | BR22: =IF(OR(AND(X22="Mourões", BQ22>=6.5),AND(X22="Postes", BQ22>=9.6),AND(X22="Dormentes", BQ22>=9.6),AND(X22="Estacas", BQ22>=6.5),AND(X22="Cruzetas", BQ22>=6.5),AND(X22="Outros - Solo", BQ22>=6.5),AND(X22="Outros - Suspenso",BQ22>=4),AND(X22="Deck",BQ22>=4)),'Listas suspensas'!$C$21,'Listas suspensas'!$C$22) -> Os resultados da análise química apresentaram uma retenção do produto inferior ao padrão mínimo exigido pela norma ABNT NBR 16143
B23: UFV-M-22 | C23: Finalizada | F23: 45377 | G23: 45377 | H23: 45383 | I23: Lagoão Tratamento de Madeira Eirelli | J23: Araranguá | K23: SC | L23: Madeira | M23: tratasul@yahoo.com.br | N23: CCA - C | O23: Torete | P23: Sem identificação | Q23: Amostra 01 - 4x6 | X23: Mourões | Y23: =IF(X23='Listas suspensas'!$A$21,'Listas suspensas'!$B$23,IF(X23='Listas suspensas'!$A$22,'Listas suspensas'!$B$23,IF(X23='Listas suspensas'!$A$23,'Listas suspensas'!$B$22,IF(X23='Listas suspensas'!$A$26,'Listas suspensas'!$B$22,IF(X23='Listas suspensas'!$A$32,'Listas suspensas'!$B$22,IF(X23='Listas suspensas'!$A$33,'Listas suspensas'!$B$21,IF(X23='Listas suspensas'!$A$24,'Listas suspensas'!$B$22,IF(X23='Listas suspensas'!$A$30,'Listas suspensas'!$B$21,"")))))))) -> 6.5 | Z23: NBR 16143 | AA23: 1 | AB23: =IF(AA23='Listas suspensas'!$A$2,'Listas suspensas'!$B$2,IF(AA23='Listas suspensas'!$A$3,'Listas suspensas'!$B$3,IF(AA23='Listas suspensas'!$A$4,'Listas suspensas'!$B$4,IF(AA23='Listas suspensas'!$A$5,'Listas suspensas'!$B$5,IF(AA23='Listas suspensas'!$A$6,'Listas suspensas'!$B$6,""))))) -> Profunda e regular | AC23: =IF(AA23='Listas suspensas'!$A$2,'Listas suspensas'!$C$2,IF(AA23='Listas suspensas'!$A$3,'Listas suspensas'!$C$3,IF(AA23='Listas suspensas'!$A$4,'Listas suspensas'!$C$4,IF(AA23='Listas suspensas'!$A$5,'Listas suspensas'!$C$5,IF(AA23='Listas suspensas'!$A$6,'Listas suspensas'!$C$6,""))))) -> Indica a penetração profunda e uniforme em toda a extensão do alburno. | AK23: 11.92 | AL23: 11.82 | AM23: 11.56 | AN23: 11.81 | AO23: 11.96 | AP23: =AVERAGE(AK23:AO23)/10 -> 1.1814 | AQ23: 8.89 | AR23: 12.08 | AS23: 20.32 | AT23: 15.24 | AU23: 13.76 | AV23: =AVERAGE(AQ23:AU23)/10 -> 1.4058 | AW23: 0.4183 | AX23: 0.6039 | AY23: 0.9759 | AZ23: 0.7573 | BA23: 0.683 | BB23: =AVERAGE(AW23:BA23) -> 0.68768 | BC23: =PI()*(AP23/2)^2*AV23 -> 1.5410167 | BE23: =(BB23/BC23)*1000 -> 446.25083 | BF23: 1.617 | BG23: 0.308 | BH23: 0.944 | BI23: =SUM(BF23:BH23) -> 2.869 | BJ23: 56.4 | BK23: 10.7 | BL23: 32.9 | BM23: =ROUND(SUM(BJ23:BL23),2) -> 100 | BN23: =ROUND((BF23/100)*BE23,2) -> 7.22 | BO23: =ROUND((BG23/100)*BE23,2) -> 1.37 | BP23: =ROUND((BH23/100)*BE23,2) -> 4.21 | BQ23: =ROUND(SUM(BN23:BP23),2) -> 12.8 | BR23: =IF(OR(AND(X23="Mourões", BQ23>=6.5),AND(X23="Postes", BQ23>=9.6),AND(X23="Dormentes", BQ23>=9.6),AND(X23="Estacas", BQ23>=6.5),AND(X23="Cruzetas", BQ23>=6.5),AND(X23="Outros - Solo", BQ23>=6.5),AND(X23="Outros - Suspenso",BQ23>=4),AND(X23="Deck",BQ23>=4)),'Listas suspensas'!$C$21,'Listas suspensas'!$C$22) -> Os resultados da análise química apresentaram uma retenção do produto de acordo com o padrão mínimo exigido pela norma ABNT NBR 16143
